Workbook
Name o: TestCases!$A$1:$A$1

Sheet Legend
A1: StreetBite V1.0 Manual QA workbook
A3: How to use it
A4: 1. | B4: Go to the TestCases sheet and run each case on a real device.
A5: 2. | B5: Fill only the yellow cells: Actual Result, Status, Device, Bug ID, Executed On.
A6: 3. | B6: Status must be Pass, Fail or Blocked (a dropdown is provided). A blank Status counts as Not Run.
A7: 4. | B7: Every Fail needs a Bug ID from Jira (for example SB-12). Add the same bug to the DefectLog sheet.
A8: 5. | B8: Traceability and Summary are formulas. Edit only the yellow cells there.
A10: Status meanings
A11: Pass | B11: Actual result matches the expected result.
A12: Fail | B12: Actual result differs from the expected result. Log a bug.
A13: Blocked | B13: The case cannot be run (state cannot be reached, feature broken by another bug). Say why in Actual Result.
A15: Severity (impact on the user)
A16: Critical | B16: App crashes, data loss, or login impossible.
A17: High | B17: A main feature is broken with no workaround.
A18: Medium | B18: A feature works but wrongly, or a workaround exists.
A19: Low | B19: Cosmetic issue or minor text problem.
A21: Example of a filled row (format only, do not copy into TestCases)
A22: TC ID | B22: Actual Result | C22: Status | D22: Device | E22: Bug ID | F22: Executed On
A23: TC_LOGIN_011 | B23: "Enter a valid email address" shown under the email field. | C23: Pass | D23: Samsung SM-A366B | E23: - | F23: 2026-10-17
A24: TC_HOME_009 | B24: Badge stayed at 1 after the second tap. | C24: Fail | D24: Samsung SM-A366B | E24: SB-12 | F24: 2026-10-17

Sheet TestCases
A1: TC ID | B1: Suite | C1: Screen | D1: Type | E1: Req | F1: Priority | G1: Title | H1: Preconditions | I1: Steps | J1: Test Data | K1: Expected Result | L1: Actual Result | M1: Status | N1: Device | O1: Bug ID | P1: Executed On
A2: TC_LOGIN_001 | B2: Login GUI | C2: Login | D2: GUI | E2: R-01 | F2: High | G2: Splash screen with fade-in | H2: App fully closed | I2: 1. Launch the app. 2. Watch the first three seconds. | J2: - | K2: Logo, "StreetBite" and the tagline "Street food, found fast" fade in. After about two seconds the Login screen opens (or Home if a session exists). | L2: The logo, 'StreetBite' and the tagline 'Street food, found fast' faded in, then the Login screen opened. | M2: Pass | N2: Samsung SM-A366B | O2: - | P2: 2026-10-16
A3: TC_LOGIN_002 | B3: Login GUI | C3: Login | D3: GUI | E3: R-13 | F3: High | G3: Login screen elements | H3: Logged out | I3: 1. Open the app and wait for Login. 2. Review the whole screen. | J3: - | K3: Logo, "Welcome back", the subtitle, Email and Password fields, the "Log in" button and the "New here? Create an account" link are visible and not cut off. | L3: Logo, 'Welcome back', 'Log in to find your next bite', the Email and Password fields (password with eye icon), the 'Log in' button and the 'New here? Create an account' link are all visible and not cut off. (Screenshot_20261016_000056.jpg) | M3: Pass | N3: Samsung SM-A366B | O3: - | P3: 2026-10-16
A4: TC_LOGIN_003 | B4: Login GUI | C4: Login | D4: GUI | E4: R-13 | F4: Medium | G4: Password visibility toggle | H4: Logged out | I4: 1. Type a password. 2. Tap the eye icon. 3. Tap it again. | J4: Password: Test1234 | K4: Password is masked by default, readable after the first tap and masked again after the second. | L4: The password was masked at first, became visible after the first tap on the eye icon and was masked again after the second tap. | M4: Pass | N4: Samsung SM-A366B | O4: - | P4: 2026-10-16
A5: TC_LOGIN_004 | B5: Login GUI | C5: Login | D5: GUI | E5: R-10 | F5: Medium | G5: Login screen in dark mode | H5: Dark mode switched on inside the app before signing out | I5: 1. Sign out. 2. Review the Login screen. | J5: - | K5: Dark colours are applied, text and fields are readable, nothing has low contrast. | L5: The Login screen used the dark colours; the text and fields were readable with no low-contrast areas. | M5: Pass | N5: Samsung SM-A366B | O5: - | P5: 2026-10-16
A6: TC_LOGIN_005 | B6: Login GUI | C6: Login | D6: GUI | E6: R-11 | F6: Medium | G6: Login screen in Arabic (RTL) | H6: Arabic selected inside the app before signing out | I6: 1. Sign out. 2. Review the Login screen. | J6: - | K6: All text is Arabic, the layout is right to left, no text overflows or is cut off. | L6: The Login screen was fully Arabic and right to left, with no text clipped or overflowing. | M6: Pass | N6: Samsung SM-A366B | O6: - | P6: 2026-10-16
A7: TC_LOGIN_006 | B7: Login Positive | C7: Login | D7: Positive | E7: R-03 | F7: High | G7: Valid login opens Home | H7: Registered account exists | I7: 1. Enter the email and password. 2. Tap "Log in". | J7: qa.tester@streetbite.test / Test1234 | K7: The button shows a spinner, then Home opens with the greeting and meals. No error is shown. | L7: The button showed a spinner, then Home opened with the greeting and the meals; no error was shown. | M7: Pass | N7: Samsung SM-A366B | O7: - | P7: 2026-10-16
A8: TC_LOGIN_007 | B8: Login Positive | C8: Login | D8: Positive | E8: R-04 | F8: High | G8: Session survives an app restart | H8: Logged in successfully | I8: 1. Close the app from recent apps. 2. Open it again. | J8: - | K8: Splash shows, then Home opens directly without asking for credentials. | L8: After closing the app from Recent apps and reopening it, the Splash appeared and Home opened directly without asking for credentials. | M8: Pass | N8: Samsung SM-A366B | O8: - | P8: 2026-10-16
A9: TC_LOGIN_008 | B9: Login Positive | C9: Login | D9: Positive | E9: R-02 | F9: Medium | G9: Open Sign up and come back | H9: Logged out | I9: 1. Tap "New here? Create an account". 2. Review the screen. 3. Press back. | J9: - | K9: Sign up shows Full name, Email, Password and Confirm password fields and a "Sign up" button. Back returns to Login. | L9: The Sign up screen opened with Full name, Email, Password, Confirm password and the 'Sign up' button; Back returned to Login. | M9: Pass | N9: Samsung SM-A366B | O9: - | P9: 2026-10-16
A10: TC_LOGIN_009 | B10: Login Positive | C10: Login | D10: Positive | E10: R-02 | F10: High | G10: Valid sign up logs the user in | H10: Email not registered yet | I10: 1. Open Sign up. 2. Fill every field. 3. Tap "Sign up". | J10: Name: Test User Email: qa.new1@streetbite.test Password: Test1234 (both fields) | K10: The Sign up screen closes by itself and Home opens with "Hi, Test". | L10: The Sign up screen closed by itself and Home opened with 'Hi, Test'. | M10: Pass | N10: Samsung SM-A366B | O10: - | P10: 2026-10-16
A11: TC_LOGIN_010 | B11: Login Negative | C11: Login | D11: Negative | E11: R-03 | F11: High | G11: Empty fields | H11: Logged out | I11: 1. Leave both fields empty. 2. Tap "Log in". | J11: - | K11: "Please enter your email" and "Please enter a password" appear under the fields. The user stays on Login. | L11: 'Please enter your email' and 'Please enter a password' appeared under the fields; the user stayed on Login. | M11: Pass | N11: Samsung SM-A366B | O11: - | P11: 2026-10-16
A12: TC_LOGIN_011 | B12: Login Negative | C12: Login | D12: Negative | E12: R-03 | F12: Medium | G12: Invalid email format | H12: Logged out | I12: 1. Enter a malformed email and a valid password. 2. Tap "Log in". | J12: Email: abc Password: Test1234 | K12: "Enter a valid email address" appears. No request is sent. | L12: 'Enter a valid email address' appeared under the Email field when a malformed email ('g') was entered. (Screenshot_20261016_000114.jpg) | M12: Pass | N12: Samsung SM-A366B | O12: - | P12: 2026-10-16
... A42: TC_HOME_021 | B42: Home General Mobile | C42: Home | D42: General Mobile | E42: R-05 | F42: Low | G42: Switch tabs and return | H42: Home loaded, one item in cart | I42: 1. Open Vendors, then Cart, then Home. | J42: - | K42: Home shows its meals without an error and the cart badge keeps its count. | L42: Home showed its meals without an error after switching tabs and returning; the cart badge kept its count. | M42: Pass | N42: Samsung SM-A366B | O42: - | P42: 2026-10-16

Sheet Traceability
A1: Req ID | B1: Requirement | C1: Assignment section | D1: Test case IDs | E1: Total | F1: Passed | G1: Failed | H1: Blocked | I1: Not Run | J1: Coverage status
A2: R-01 | B2: Splash/onboarding screen with a fade-in animation | C2: Onboarding, Login and Sign Up | D2: TC_LOGIN_001 | E2: =COUNTIF(TestCases!$E$2:$E$200,A2) -> 1 | F2: =COUNTIFS(TestCases!$E$2:$E$200,A2,TestCases!$M$2:$M$200,"Pass") -> 1 | G2: =COUNTIFS(TestCases!$E$2:$E$200,A2,TestCases!$M$2:$M$200,"Fail") -> 0 | H2: =COUNTIFS(TestCases!$E$2:$E$200,A2,TestCases!$M$2:$M$200,"Blocked") -> 0 | I2: =E2-F2-G2-H2 -> 0 | J2: =IF(E2=0,"No coverage",IF(G2>0,"Failing",IF(F2=E2,"Covered and passed",IF(I2=E2,"Not run","In progress")))) -> Covered and passed
A3: R-02 | B3: Sign-up validation: full name with capital first letter, email, password of at least six characters, password confirmation | C3: Onboarding, Login and Sign Up | D3: TC_LOGIN_008, TC_LOGIN_009, TC_LOGIN_014, TC_LOGIN_015, TC_LOGIN_016, TC_LOGIN_017 | E3: =COUNTIF(TestCases!$E$2:$E$200,A3) -> 6 | F3: =COUNTIFS(TestCases!$E$2:$E$200,A3,TestCases!$M$2:$M$200,"Pass") -> 6 | G3: =COUNTIFS(TestCases!$E$2:$E$200,A3,TestCases!$M$2:$M$200,"Fail") -> 0 | H3: =COUNTIFS(TestCases!$E$2:$E$200,A3,TestCases!$M$2:$M$200,"Blocked") -> 0 | I3: =E3-F3-G3-H3 -> 0 | J3: =IF(E3=0,"No coverage",IF(G3>0,"Failing",IF(F3=E3,"Covered and passed",IF(I3=E3,"Not run","In progress")))) -> Covered and passed
A4: R-03 | B4: Firebase Authentication login with friendly error messages | C4: Onboarding, Login and Sign Up | D4: TC_LOGIN_006, TC_LOGIN_010, TC_LOGIN_011, TC_LOGIN_012, TC_LOGIN_013, TC_LOGIN_018, TC_LOGIN_019 | E4: =COUNTIF(TestCases!$E$2:$E$200,A4) -> 7 | F4: =COUNTIFS(TestCases!$E$2:$E$200,A4,TestCases!$M$2:$M$200,"Pass") -> 7 | G4: =COUNTIFS(TestCases!$E$2:$E$200,A4,TestCases!$M$2:$M$200,"Fail") -> 0 | H4: =COUNTIFS(TestCases!$E$2:$E$200,A4,TestCases!$M$2:$M$200,"Blocked") -> 0 | I4: =E4-F4-G4-H4 -> 0 | J4: =IF(E4=0,"No coverage",IF(G4>0,"Failing",IF(F4=E4,"Covered and passed",IF(I4=E4,"Not run","In progress")))) -> Covered and passed
A5: R-04 | B5: Authentication state persists across app restarts | C5: Onboarding, Login and Sign Up | D5: TC_LOGIN_007 | E5: =COUNTIF(TestCases!$E$2:$E$200,A5) -> 1 | F5: =COUNTIFS(TestCases!$E$2:$E$200,A5,TestCases!$M$2:$M$200,"Pass") -> 1 | G5: =COUNTIFS(TestCases!$E$2:$E$200,A5,TestCases!$M$2:$M$200,"Fail") -> 0 | H5: =COUNTIFS(TestCases!$E$2:$E$200,A5,TestCases!$M$2:$M$200,"Blocked") -> 0 | I5: =E5-F5-G5-H5 -> 0 | J5: =IF(E5=0,"No coverage",IF(G5>0,"Failing",IF(F5=E5,"Covered and passed",IF(I5=E5,"Not run","In progress")))) -> Covered and passed
A6: R-05 | B6: Home screen responsive layout (MediaQuery) with a PageView banner of featured meals | C6: Home Screen and Live Menu | D6: TC_HOME_001, TC_HOME_002, TC_HOME_019, TC_HOME_020, TC_HOME_021 | E6: =COUNTIF(TestCases!$E$2:$E$200,A6) -> 5 | F6: =COUNTIFS(TestCases!$E$2:$E$200,A6,TestCases!$M$2:$M$200,"Pass") -> 5 | G6: =COUNTIFS(TestCases!$E$2:$E$200,A6,TestCases!$M$2:$M$200,"Fail") -> 0 | H6: =COUNTIFS(TestCases!$E$2:$E$200,A6,TestCases!$M$2:$M$200,"Blocked") -> 0 | I6: =E6-F6-G6-H6 -> 0 | J6: =IF(E6=0,"No coverage",IF(G6>0,"Failing",IF(F6=E6,"Covered and passed",IF(I6=E6,"Not run","In progress")))) -> Covered and passed
A7: R-06 | B7: Meals fetched from TheMealDB with Dio, with loading and friendly error states | C7: Home Screen and Live Menu | D7: TC_HOME_007, TC_HOME_012, TC_HOME_016 | E7: =COUNTIF(TestCases!$E$2:$E$200,A7) -> 3 | F7: =COUNTIFS(TestCases!$E$2:$E$200,A7,TestCases!$M$2:$M$200,"Pass") -> 2 | G7: =COUNTIFS(TestCases!$E$2:$E$200,A7,TestCases!$M$2:$M$200,"Fail") -> 0 | H7: =COUNTIFS(TestCases!$E$2:$E$200,A7,TestCases!$M$2:$M$200,"Blocked") -> 1 | I7: =E7-F7-G7-H7 -> 0 | J7: =IF(E7=0,"No coverage",IF(G7>0,"Failing",IF(F7=E7,"Covered and passed",IF(I7=E7,"Not run","In progress")))) -> In progress
A8: R-07 | B8: Meal data cached with shared_preferences and restored on restart | C8: Home Screen and Live Menu | D8: TC_HOME_014 | E8: =COUNTIF(TestCases!$E$2:$E$200,A8) -> 1 | F8: =COUNTIFS(TestCases!$E$2:$E$200,A8,TestCases!$M$2:$M$200,"Pass") -> 0 | G8: =COUNTIFS(TestCases!$E$2:$E$200,A8,TestCases!$M$2:$M$200,"Fail") -> 1 | H8: =COUNTIFS(TestCases!$E$2:$E$200,A8,TestCases!$M$2:$M$200,"Blocked") -> 0 | I8: =E8-F8-G8-H8 -> 0 | J8: =IF(E8=0,"No coverage",IF(G8>0,"Failing",IF(F8=E8,"Covered and passed",IF(I8=E8,"Not run","In progress")))) -> Failing
A9: R-08 | B9: Two-column meals grid with Add to Cart action and SnackBar | C9: Home Screen and Live Menu | D9: TC_HOME_004, TC_HOME_008, TC_HOME_009, TC_HOME_013, TC_HOME_017, TC_HOME_018 | E9: =COUNTIF(TestCases!$E$2:$E$200,A9) -> 6 | F9: =COUNTIFS(TestCases!$E$2:$E$200,A9,TestCases!$M$2:$M$200,"Pass") -> 6 | G9: =COUNTIFS(TestCases!$E$2:$E$200,A9,TestCases!$M$2:$M$200,"Fail") -> 0 | H9: =COUNTIFS(TestCases!$E$2:$E$200,A9,TestCases!$M$2:$M$200,"Blocked") -> 0 | I9: =E9-F9-G9-H9 -> 0 | J9: =IF(E9=0,"No coverage",IF(G9>0,"Failing",IF(F9=E9,"Covered and passed",IF(I9=E9,"Not run","In progress")))) -> Covered and passed
A10: R-09 | B10: Horizontal Hot Offers list with five items | C10: Home Screen and Live Menu | D10: TC_HOME_003 | E10: =COUNTIF(TestCases!$E$2:$E$200,A10) -> 1 | F10: =COUNTIFS(TestCases!$E$2:$E$200,A10,TestCases!$M$2:$M$200,"Pass") -> 1 | G10: =COUNTIFS(TestCases!$E$2:$E$200,A10,TestCases!$M$2:$M$200,"Fail") -> 0 | H10: =COUNTIFS(TestCases!$E$2:$E$200,A10,TestCases!$M$2:$M$200,"Blocked") -> 0 | I10: =E10-F10-G10-H10 -> 0 | J10: =IF(E10=0,"No coverage",IF(G10>0,"Failing",IF(F10=E10,"Covered and passed",IF(I10=E10,"Not run","In progress")))) -> Covered and passed
A11: R-10 | B11: Light and dark theme toggle connected to ThemeBloc | C11: Home Screen and Live Menu | D11: TC_LOGIN_004, TC_HOME_005, TC_HOME_015 | E11: =COUNTIF(TestCases!$E$2:$E$200,A11) -> 3 | F11: =COUNTIFS(TestCases!$E$2:$E$200,A11,TestCases!$M$2:$M$200,"Pass") -> 3 | G11: =COUNTIFS(TestCases!$E$2:$E$200,A11,TestCases!$M$2:$M$200,"Fail") -> 0 | H11: =COUNTIFS(TestCases!$E$2:$E$200,A11,TestCases!$M$2:$M$200,"Blocked") -> 0 | I11: =E11-F11-G11-H11 -> 0 | J11: =IF(E11=0,"No coverage",IF(G11>0,"Failing",IF(F11=E11,"Covered and passed",IF(I11=E11,"Not run","In progress")))) -> Covered and passed
A12: R-11 | B12: Runtime English/Arabic toggle with every visible string localized | C12: English and Arabic Localization | D12: TC_LOGIN_005, TC_HOME_006 | E12: =COUNTIF(TestCases!$E$2:$E$200,A12) -> 2 | F12: =COUNTIFS(TestCases!$E$2:$E$200,A12,TestCases!$M$2:$M$200,"Pass") -> 2 | G12: =COUNTIFS(TestCases!$E$2:$E$200,A12,TestCases!$M$2:$M$200,"Fail") -> 0 | H12: =COUNTIFS(TestCases!$E$2:$E$200,A12,TestCases!$M$2:$M$200,"Blocked") -> 0 | I12: =E12-F12-G12-H12 -> 0 | J12: =IF(E12=0,"No coverage",IF(G12>0,"Failing",IF(F12=E12,"Covered and passed",IF(I12=E12,"Not run","In progress")))) -> Covered and passed
A13: R-12 | B13: Meal details open from a meal card with the selected meal passed as an argument | C13: Meal Details and Favourites | D13: TC_HOME_010, TC_HOME_011 | E13: =COUNTIF(TestCases!$E$2:$E$200,A13) -> 2 | F13: =COUNTIFS(TestCases!$E$2:$E$200,A13,TestCases!$M$2:$M$200,"Pass") -> 2 | G13: =COUNTIFS(TestCases!$E$2:$E$200,A13,TestCases!$M$2:$M$200,"Fail") -> 0 | H13: =COUNTIFS(TestCases!$E$2:$E$200,A13,TestCases!$M$2:$M$200,"Blocked") -> 0 | I13: =E13-F13-G13-H13 -> 0 | J13: =IF(E13=0,"No coverage",IF(G13>0,"Failing",IF(F13=E13,"Covered and passed",IF(I13=E13,"Not run","In progress")))) -> Covered and passed
A14: R-13 | B14: Login screen layout: logo, fields, password visibility and sign-up link | C14: Onboarding, Login and Sign Up | D14: TC_LOGIN_002, TC_LOGIN_003, TC_LOGIN_020 | E14: =COUNTIF(TestCases!$E$2:$E$200,A14) -> 3 | F14: =COUNTIFS(TestCases!$E$2:$E$200,A14,TestCases!$M$2:$M$200,"Pass") -> 3 | G14: =COUNTIFS(TestCases!$E$2:$E$200,A14,TestCases!$M$2:$M$200,"Fail") -> 0 | H14: =COUNTIFS(TestCases!$E$2:$E$200,A14,TestCases!$M$2:$M$200,"Blocked") -> 0 | I14: =E14-F14-G14-H14 -> 0 | J14: =IF(E14=0,"No coverage",IF(G14>0,"Failing",IF(F14=E14,"Covered and passed",IF(I14=E14,"Not run","In progress")))) -> Covered and passed
A16: Note: the Test case IDs column is plain text built from the Req column in TestCases. If you change a Req value there, update this column by hand. All counts are live formulas.

Sheet DefectLog
A1: Jira key | B1: Title | C1: Linked TC | D1: Severity | E1: Priority | F1: Status | G1: Found on | H1: Screenshot file
A2: SB-1 | B2: Cached meals are shown without photos when the phone is offline | C2: TC_HOME_014 | D2: Medium | E2: Low | F2: Open | G2: 2026-10-16 | H2: TC_HOME_014.png

Sheet Summary
A1: Test execution summary and closure
A3: Scope and environment
A4: Application | B4: StreetBite V1.0 (1.0.0+1)
A5: Build under test | B5: Debug APK
A6: Primary device | B6: Samsung SM-A366B (real device)
A7: Secondary device | B7: Android emulator
A8: Tester | B8: Shahd Zain
A9: Test period | B9: 2026-10-16 to 2026-10-18
A10: Defect tracker | B10: Jira
A11: Yellow cells above are assumptions taken from the project setup. Edit them if they changed.
A13: Execution results
A14: Group | C14: Total | D14: Pass | E14: Fail | F14: Blocked | G14: Not run
A15: All cases | C15: =COUNTA(TestCases!$A$2:$A$200) -> 41 | D15: =COUNTIF(TestCases!$M$2:$M$200,"Pass") -> 39 | E15: =COUNTIF(TestCases!$M$2:$M$200,"Fail") -> 1 | F15: =COUNTIF(TestCases!$M$2:$M$200,"Blocked") -> 1 | G15: =C15-D15-E15-F15 -> 0
A16: Screen: Login | C16: =COUNTIF(TestCases!$C$2:$C$200,"Login") -> 20 | D16: =COUNTIFS(TestCases!$C$2:$C$200,"Login",TestCases!$M$2:$M$200,"Pass") -> 20 | E16: =COUNTIFS(TestCases!$C$2:$C$200,"Login",TestCases!$M$2:$M$200,"Fail") -> 0 | F16: =COUNTIFS(TestCases!$C$2:$C$200,"Login",TestCases!$M$2:$M$200,"Blocked") -> 0 | G16: =C16-D16-E16-F16 -> 0
A17: Screen: Home | C17: =COUNTIF(TestCases!$C$2:$C$200,"Home") -> 21 | D17: =COUNTIFS(TestCases!$C$2:$C$200,"Home",TestCases!$M$2:$M$200,"Pass") -> 19 | E17: =COUNTIFS(TestCases!$C$2:$C$200,"Home",TestCases!$M$2:$M$200,"Fail") -> 1 | F17: =COUNTIFS(TestCases!$C$2:$C$200,"Home",TestCases!$M$2:$M$200,"Blocked") -> 1 | G17: =C17-D17-E17-F17 -> 0
A18: Type: GUI | C18: =COUNTIF(TestCases!$D$2:$D$200,"GUI") -> 11 | D18: =COUNTIFS(TestCases!$D$2:$D$200,"GUI",TestCases!$M$2:$M$200,"Pass") -> 11 | E18: =COUNTIFS(TestCases!$D$2:$D$200,"GUI",TestCases!$M$2:$M$200,"Fail") -> 0 | F18: =COUNTIFS(TestCases!$D$2:$D$200,"GUI",TestCases!$M$2:$M$200,"Blocked") -> 0 | G18: =C18-D18-E18-F18 -> 0
A19: Type: Positive | C19: =COUNTIF(TestCases!$D$2:$D$200,"Positive") -> 13 | D19: =COUNTIFS(TestCases!$D$2:$D$200,"Positive",TestCases!$M$2:$M$200,"Pass") -> 12 | E19: =COUNTIFS(TestCases!$D$2:$D$200,"Positive",TestCases!$M$2:$M$200,"Fail") -> 1 | F19: =COUNTIFS(TestCases!$D$2:$D$200,"Positive",TestCases!$M$2:$M$200,"Blocked") -> 0 | G19: =C19-D19-E19-F19 -> 0
A20: Type: Negative | C20: =COUNTIF(TestCases!$D$2:$D$200,"Negative") -> 11 | D20: =COUNTIFS(TestCases!$D$2:$D$200,"Negative",TestCases!$M$2:$M$200,"Pass") -> 10 | E20: =COUNTIFS(TestCases!$D$2:$D$200,"Negative",TestCases!$M$2:$M$200,"Fail") -> 0 | F20: =COUNTIFS(TestCases!$D$2:$D$200,"Negative",TestCases!$M$2:$M$200,"Blocked") -> 1 | G20: =C20-D20-E20-F20 -> 0
A21: Type: General Mobile | C21: =COUNTIF(TestCases!$D$2:$D$200,"General Mobile") -> 6 | D21: =COUNTIFS(TestCases!$D$2:$D$200,"General Mobile",TestCases!$M$2:$M$200,"Pass") -> 6 | E21: =COUNTIFS(TestCases!$D$2:$D$200,"General Mobile",TestCases!$M$2:$M$200,"Fail") -> 0 | F21: =COUNTIFS(TestCases!$D$2:$D$200,"General Mobile",TestCases!$M$2:$M$200,"Blocked") -> 0 | G21: =C21-D21-E21-F21 -> 0
A22: Pass rate (of executed cases) | C22: =IF((D15+E15+F15)=0,0,D15/(D15+E15+F15)) -> 0.95121951
A23: Executed (Pass + Fail + Blocked) | C23: =IF(C15=0,0,(D15+E15+F15)/C15) -> 1
A25: Defects (from DefectLog)
A26: Severity | C26: Total | D26: Not closed
A27: Critical | C27: =COUNTIF(DefectLog!$D$2:$D$200,"Critical") -> 0 | D27: =COUNTIFS(DefectLog!$D$2:$D$200,"Critical",DefectLog!$F$2:$F$200,"<>Closed") -> 0
A28: High | C28: =COUNTIF(DefectLog!$D$2:$D$200,"High") -> 0 | D28: =COUNTIFS(DefectLog!$D$2:$D$200,"High",DefectLog!$F$2:$F$200,"<>Closed") -> 0
A29: Medium | C29: =COUNTIF(DefectLog!$D$2:$D$200,"Medium") -> 1 | D29: =COUNTIFS(DefectLog!$D$2:$D$200,"Medium",DefectLog!$F$2:$F$200,"<>Closed") -> 1
A30: Low | C30: =COUNTIF(DefectLog!$D$2:$D$200,"Low") -> 0 | D30: =COUNTIFS(DefectLog!$D$2:$D$200,"Low",DefectLog!$F$2:$F$200,"<>Closed") -> 0
A32: Exit criteria
A33: Criterion | B33: Target | C33: Actual | D33: Result
A34: Minimum pass rate | B34: 0.9 | C34: =C22 -> 0.95121951 | D34: =IF(C34>=B34,"Met","Not met") -> Met
A35: All planned cases executed | B35: 1 | C35: =C23 -> 1 | D35: =IF(C35>=B35,"Met","Not met") -> Met
A36: No open Critical or High defects | B36: 0 | C36: =D27+D28 -> 0 | D36: =IF(C36<=B36,"Met","Not met") -> Met
A37: Every Fail has a Bug ID | B37: 0 | C37: =COUNTIFS(TestCases!$M$2:$M$200,"Fail",TestCases!$O$2:$O$200,"") -> 0 | D37: =IF(C37<=B37,"Met","Not met") -> Met
A38: Every requirement has at least one case | B38: 0 | C38: =COUNTIF(Traceability!$E$2:$E$14,0) -> 0 | D38: =IF(C38<=B38,"Met","Not met") -> Met
A39: Overall exit decision | C39: =IF(COUNTIF(D34:D38,"Met")=ROWS(D34:D38),"Exit criteria met","Exit criteria not met") -> Exit criteria met
A41: Closure summary (fill in after execution)
A42: Overall outcome | B42: 41 cases were executed on the Samsung SM-A366B: 39 Pass, 1 Fail and 1 Blocked (pass rate 95.1%). All exit criteria are met.
A43: Main findings | B43: Login (validation, wrong and unknown credentials, session persistence, offline message) and Home (banner, Hot Offers, grid, cart, theme and language, cache) behave as specified. One defect was found: SB-1, cached meals are shown without photos when the phone is offline (TC_HOME_014). The smoke checklists from the Test Plan (Meal Details, Cart, Vendor Map and Profile) were also run on the Samsung SM-A366B and worked as described; no defects were found there.
A44: Open risks and known issues | B44: SB-1 is open (Medium severity, Low priority). TC_HOME_016 (meal service down with no cache) is Blocked because meals are cached after the first load and the meal API is reachable, so that error state could not be produced. Only one physical device was used.
A45: Recommendation | B45: Ready for the beta release. Cache the meal photos so that Home looks complete offline, then re-test TC_HOME_014 on the same device.
...
